[2025-01-24T13:37:23.311+0000] {local_task_job_runner.py:123} INFO - ::group::Pre task execution logs
[2025-01-24T13:37:23.331+0000] {taskinstance.py:2612} INFO - Dependencies all met for dep_context=non-requeueable deps ti=<TaskInstance: detect_data_drift_notify_retrain.detect_file_task manual__2025-01-24T13:37:19.638591+00:00 [queued]>
[2025-01-24T13:37:23.337+0000] {taskinstance.py:2612} INFO - Dependencies all met for dep_context=requeueable deps ti=<TaskInstance: detect_data_drift_notify_retrain.detect_file_task manual__2025-01-24T13:37:19.638591+00:00 [queued]>
[2025-01-24T13:37:23.339+0000] {taskinstance.py:2865} INFO - Starting attempt 1 of 2
[2025-01-24T13:37:23.351+0000] {taskinstance.py:2888} INFO - Executing <Task(BranchPythonOperator): detect_file_task> on 2025-01-24 13:37:19.638591+00:00
[2025-01-24T13:37:23.363+0000] {warnings.py:112} WARNING - /home/***/.local/lib/python3.12/site-packages/***/task/task_runner/standard_task_runner.py:70: DeprecationWarning: This process (pid=1502) is multi-threaded, use of fork() may lead to deadlocks in the child.
  pid = os.fork()

[2025-01-24T13:37:23.365+0000] {standard_task_runner.py:72} INFO - Started process 1523 to run task
[2025-01-24T13:37:23.365+0000] {standard_task_runner.py:104} INFO - Running: ['***', 'tasks', 'run', 'detect_data_drift_notify_retrain', 'detect_file_task', 'manual__2025-01-24T13:37:19.638591+00:00', '--job-id', '6', '--raw', '--subdir', 'DAGS_FOLDER/monitoring-dag.py', '--cfg-path', '/tmp/tmp__z9mzb0']
[2025-01-24T13:37:23.367+0000] {standard_task_runner.py:105} INFO - Job 6: Subtask detect_file_task
[2025-01-24T13:37:23.408+0000] {task_command.py:467} INFO - Running <TaskInstance: detect_data_drift_notify_retrain.detect_file_task manual__2025-01-24T13:37:19.638591+00:00 [running]> on host 73fe75389ff6
[2025-01-24T13:37:23.472+0000] {taskinstance.py:3131} INFO - Exporting env vars: AIRFLOW_CTX_DAG_OWNER='RL' AIRFLOW_CTX_DAG_ID='detect_data_drift_notify_retrain' AIRFLOW_CTX_TASK_ID='detect_file_task' AIRFLOW_CTX_EXECUTION_DATE='2025-01-24T13:37:19.638591+00:00' AIRFLOW_CTX_TRY_NUMBER='1' AIRFLOW_CTX_DAG_RUN_ID='manual__2025-01-24T13:37:19.638591+00:00'
[2025-01-24T13:37:23.473+0000] {taskinstance.py:731} INFO - ::endgroup::
[2025-01-24T13:37:23.484+0000] {baseoperator.py:405} WARNING - BranchPythonOperator.execute cannot be called outside TaskInstance!
[2025-01-24T13:37:23.499+0000] {credentials.py:1147} INFO - Found credentials in environment variables.
[2025-01-24T13:37:23.579+0000] {monitoring-dag.py:49} INFO - Checking file in S3: 4-final-project/covertype/new_data/covtype_sample_drift.csv
[2025-01-24T13:37:24.325+0000] {monitoring-dag.py:54} ERROR - Error checking S3: An error occurred (404) when calling the HeadObject operation: Not Found
[2025-01-24T13:37:24.329+0000] {python.py:240} INFO - Done. Returned value was: no_file_found_task
[2025-01-24T13:37:24.332+0000] {branch.py:38} INFO - Branch into no_file_found_task
[2025-01-24T13:37:24.333+0000] {skipmixin.py:230} INFO - Following branch ('no_file_found_task',)
[2025-01-24T13:37:24.344+0000] {skipmixin.py:278} INFO - Skipping tasks [('detect_data_drift_task', -1)]
[2025-01-24T13:37:24.367+0000] {taskinstance.py:340} INFO - ::group::Post task execution logs
[2025-01-24T13:37:24.368+0000] {taskinstance.py:352} INFO - Marking task as SUCCESS. dag_id=detect_data_drift_notify_retrain, task_id=detect_file_task, run_id=manual__2025-01-24T13:37:19.638591+00:00, execution_date=20250124T133719, start_date=20250124T133723, end_date=20250124T133724
[2025-01-24T13:37:24.384+0000] {local_task_job_runner.py:266} INFO - Task exited with return code 0
[2025-01-24T13:37:24.408+0000] {taskinstance.py:3900} INFO - 0 downstream tasks scheduled from follow-on schedule check
[2025-01-24T13:37:24.411+0000] {local_task_job_runner.py:245} INFO - ::endgroup::
